Workbook

Sheet Данные
A1: Возраст опрашиваемых, лет | D1: Кол-во программистов, f_i | E1: Накопленные частоты | H1: 15 | I1: 33 | J1: 27 | K1: 25 | L1: 29 | M1: 35 | N1: 27 | O1: 34 | P1: 28 | Q1: 38 | R1: 25 | S1: 41 | T1: 26 | U1: 32 | V1: 32
H2: 22 | I2: 48 | J2: 20 | K2: 34 | L2: 26 | M2: 19 | N2: 34 | O2: 24 | P2: 23 | Q2: 27 | R2: 24 | S2: 27 | T2: 49 | U2: 24 | V2: 28
A3: 15 | B3: =20 -> 20 | C3: =20-0.001 -> 19.999 | D3: {=FREQUENCY(H1:V11,C3:C11)} -> 6 | E3: =SUM($D$3:D3) -> 6 | H3: 29 | I3: 33 | J3: 36 | K3: 24 | L3: 43 | M3: 26 | N3: 28 | O3: 26 | P3: 28 | Q3: 18 | R3: 26 | S3: 43 | T3: 21 | U3: 54 | V3: 40
A4: 20 | B4: =25 -> 25 | C4: =25-0.001 -> 24.999 | D4: 15 | E4: =SUM($D$3:D4) -> 21 | H4: 32 | I4: 49 | J4: 29 | K4: 34 | L4: 29 | M4: 44 | N4: 16 | O4: 28 | P4: 27 | Q4: 28 | R4: 26 | S4: 28 | T4: 51 | U4: 27 | V4: 59
A5: 25 | B5: =30 -> 30 | C5: =30-0.001 -> 29.999 | D5: 57 | E5: =SUM($D$3:D5) -> 78 | H5: 38 | I5: 23 | J5: 27 | K5: 28 | L5: 25 | M5: 32 | N5: 47 | O5: 26 | P5: 35 | Q5: 25 | R5: 28 | S5: 36 | T5: 33 | U5: 27 | V5: 25
A6: 30 | B6: =35 -> 35 | C6: =35-0.001 -> 34.999 | D6: 17 | E6: =SUM($D$3:D6) -> 95 | H6: 40 | I6: 48 | J6: 29 | K6: 19 | L6: 33 | M6: 27 | N6: 26 | O6: 26 | P6: 34 | Q6: 23 | R6: 27 | S6: 26 | T6: 18 | U6: 49 | V6: 49
A7: 35 | B7: =40 -> 40 | C7: =40-0.001 -> 39.999 | D7: 12 | E7: =SUM($D$3:D7) -> 107 | H7: 48 | I7: 43 | J7: 27 | K7: 45 | L7: 25 | M7: 38 | N7: 20 | O7: 25 | P7: 28 | Q7: 43 | R7: 27 | S7: 51 | T7: 48 | U7: 27 | V7: 22
A8: 40 | B8: =45 -> 45 | C8: =45-0.001 -> 44.999 | D8: 14 | E8: =SUM($D$3:D8) -> 121 | H8: 51 | I8: 51 | J8: 26 | K8: 28 | L8: 24 | M8: 30 | N8: 42 | O8: 29 | P8: 27 | Q8: 25 | R8: 21 | S8: 27 | T8: 25 | U8: 60 | V8: 26
A9: 45 | B9: =50 -> 50 | C9: =50-0.001 -> 49.999 | D9: 20 | E9: =SUM($D$3:D9) -> 141 | H9: 58 | I9: 22 | J9: 59 | K9: 52 | L9: 33 | M9: 31 | N9: 27 | O9: 54 | P9: 26 | Q9: 32 | R9: 51 | S9: 48 | T9: 46 | U9: 28 | V9: 37
A10: 50 | B10: =55 -> 55 | C10: =55-0.001 -> 54.999 | D10: 11 | E10: =SUM($D$3:D10) -> 152 | H10: 38 | I10: 54 | J10: 44 | K10: 39 | L10: 54 | M10: 43 | N10: 38 | O10: 42 | P10: 51 | Q10: 46 | R10: 35 | S10: 41 | T10: 42 | U10: 45 | V10: 45
A11: 55 | B11: =60 -> 60 | C11: =60+0.001 -> 60.001 | D11: 8 | E11: =SUM($D$3:D11) -> 160 | H11: 59 | I11: 49 | J11: 58 | K11: 58 | L11: 47 | M11: 59 | N11: 48 | O11: 48 | P11: 45 | Q11: 25
A12: Итого: | D12: =SUM(D3:D11) -> 160
A14: max | B14: 60
A15: min | B15: 15
A17: n | B17: 160
A19: k | B19: =1+1.4*LN(B17) -> 8.1052433
B20: 9
A22: ∆ | B22: =(B14-B15)/B20 -> 5

Sheet Числ характер распред
A1: 1. Характеристики положения (средняя арифметическая, мода, медиана).
A3: Ср ар ( x̅ ) | B3: =SUM(C6:C14)/SUM(Данные!D3:D11) -> 34.96875 | G3: Mo | H3: =25+5*((Данные!D5-Данные!D4)/((Данные!D5-Данные!D4)+(Данные!D5-Данные!D6))) -> 27.560976 | M3: Me | N3: =30+5*((0.5*SUM(Данные!D3:D11)-Данные!E5)/Данные!D6) -> 30.588235
A5: x' | C5: x' * f_i | G5: Mo интервал | I5: 25 - 30 | M5: Me интервал | O5: 30 - 35
A6: =(Данные!A3+Данные!B3)/2 -> 17.5 | C6: =A6*Данные!D3 -> 105
A7: =(Данные!A4+Данные!B4)/2 -> 22.5 | C7: =A7*Данные!D4 -> 337.5
A8: =(Данные!A5+Данные!B5)/2 -> 27.5 | C8: =A8*Данные!D5 -> 1567.5
A9: =(Данные!A6+Данные!B6)/2 -> 32.5 | C9: =A9*Данные!D6 -> 552.5
A10: =(Данные!A7+Данные!B7)/2 -> 37.5 | C10: =A10*Данные!D7 -> 450
A11: =(Данные!A8+Данные!B8)/2 -> 42.5 | C11: =A11*Данные!D8 -> 595
A12: =(Данные!A9+Данные!B9)/2 -> 47.5 | C12: =A12*Данные!D9 -> 950
A13: =(Данные!A10+Данные!B10)/2 -> 52.5 | C13: =A13*Данные!D10 -> 577.5
A14: =(Данные!A11+Данные!B11)/2 -> 57.5 | C14: =A14*Данные!D11 -> 460
A16: 2. Характеристики рассеяния (дисперсия, среднее квадратическое отклонение, коэффициент вариации).
A18: Дисперсия | B18: =SUM(A21:B29)/SUM(Данные!D3:D11) -> 118.12402 | E18: Ср кв откл (σ) | G18: =SQRT(B18) -> 10.868488 | J18: Коэф вар | L18: =G18/B3 -> 0.31080572
A20: f_i * (x' - x̅)^2
A21: =Данные!D3*(A6-$B$3)^2 -> 1830.9434
A22: =Данные!D4*(A7-$B$3)^2 -> 2332.0459
A23: =Данные!D5*(A8-$B$3)^2 -> 3179.5869
A24: =Данные!D6*(A9-$B$3)^2 -> 103.61035
A25: =Данные!D7*(A10-$B$3)^2 -> 76.886719
A26: =Данные!D8*(A11-$B$3)^2 -> 794.07617
A27: =Данные!D9*(A12-$B$3)^2 -> 3140.6445
A28: =Данные!D10*(A13-$B$3)^2 -> 3380.792
A29: =Данные!D11*(A14-$B$3)^2 -> 4061.2578
A31: 3. Характеристики меры скошенности (коэффициент асимметрии).
A33: Коэф асимметрии | C33: =E35/G18^3 -> 0.54154687
A35: f_i * (x' - x̅)^3 | D35: M3 | E35: =SUM(A36:B44)/Данные!D12 -> 695.25385
A36: =Данные!D3*(A6-$B$3)^3 -> -31984.292
A37: =Данные!D4*(A7-$B$3)^3 -> -29077.697
A38: =Данные!D5*(A8-$B$3)^3 -> -23747.54
A39: =Данные!D6*(A9-$B$3)^3 -> -255.78806
A40: =Данные!D7*(A10-$B$3)^3 -> 194.61951
A41: =Данные!D8*(A11-$B$3)^3 -> 5980.3862
A42: =Данные!D9*(A12-$B$3)^3 -> 39356.202
A43: =Данные!D10*(A13-$B$3)^3 -> 59269.51
A44: =Данные!D11*(A14-$B$3)^3 -> 91505.215
A46: 4. Характеристики островершенности (эксцесс).
A48: Эксцесс | C48: =(E50/G18^4)-3 -> -0.87738409
A50: f_i * (x' - x̅)^4 | D50: M4 | E50: =SUM(A51:B59)/Данные!D12 -> 29617.465
A51: =Данные!D3*(A6-$B$3)^4 -> 558725.6
...

Sheet Проверка на нормаль
A1: Возраст опрашиваемых, лет | D1: Кол-во программистов, f_i | F1: Середина интервала, x_i
A4: 15 | B4: - | C4: 20 | D4: 6 | F4: =A4+(C4-A4)/2 -> 17.5 | H4: =(F4-'Числ характер распред'!$B$3)/('Числ характер распред'!$G$18) -> -1.6072843 | J4: 0.1092 | L4: =J4*($D$13*5)/'Числ характер распред'!$G$18 -> 8.0379169 | N4: 8
A5: 20 | B5: - | C5: 25 | D5: 15 | F5: =A5+(C5-A5)/2 -> 22.5 | H5: =(F5-'Числ характер распред'!$B$3)/('Числ характер распред'!$G$18) -> -1.1472387 | J5: 0.2059 | L5: =J5*($D$13*5)/'Числ характер распред'!$G$18 -> 15.155743 | N5: 15
A6: 25 | B6: - | C6: 30 | D6: 57 | F6: =A6+(C6-A6)/2 -> 27.5 | H6: =(F6-'Числ характер распред'!$B$3)/('Числ характер распред'!$G$18) -> -0.68719313 | J6: 0.3114 | L6: =J6*($D$13*5)/'Числ характер распред'!$G$18 -> 22.921312 | N6: 23
A7: 30 | B7: - | C7: 35 | D7: 17 | F7: =A7+(C7-A7)/2 -> 32.5 | H7: =(F7-'Числ характер распред'!$B$3)/('Числ характер распред'!$G$18) -> -0.22714752 | J7: 0.3885 | L7: =J7*($D$13*5)/'Числ характер распред'!$G$18 -> 28.596435 | N7: 29
A8: 35 | B8: - | C8: 40 | D8: 12 | F8: =A8+(C8-A8)/2 -> 37.5 | H8: =(F8-'Числ характер распред'!$B$3)/('Числ характер распред'!$G$18) -> 0.23289809 | J8: 0.3885 | L8: =J8*($D$13*5)/'Числ характер распред'!$G$18 -> 28.596435 | N8: 29
A9: 40 | B9: - | C9: 45 | D9: 14 | F9: =A9+(C9-A9)/2 -> 42.5 | H9: =(F9-'Числ характер распред'!$B$3)/('Числ характер распред'!$G$18) -> 0.6929437 | J9: 0.3114 | L9: =J9*($D$13*5)/'Числ характер распред'!$G$18 -> 22.921312 | N9: 23
A10: 45 | B10: - | C10: 50 | D10: 20 | F10: =A10+(C10-A10)/2 -> 47.5 | H10: =(F10-'Числ характер распред'!$B$3)/('Числ характер распред'!$G$18) -> 1.1529893 | J10: 0.2059 | L10: =J10*($D$13*5)/'Числ характер распред'!$G$18 -> 15.155743 | N10: 15
A11: 50 | B11: - | C11: 55 | D11: 11 | F11: =A11+(C11-A11)/2 -> 52.5 | H11: =(F11-'Числ характер распред'!$B$3)/('Числ характер распред'!$G$18) -> 1.6130349 | J11: 0.1092 | L11: =J11*($D$13*5)/'Числ характер распред'!$G$18 -> 8.0379169 | N11: 8
A12: 55 | B12: - | C12: 60 | D12: 8 | F12: =A12+(C12-A12)/2 -> 57.5 | H12: =(F12-'Числ характер распред'!$B$3)/('Числ характер распред'!$G$18) -> 2.0730805 | J12: 0.0468 | L12: =J12*($D$13*5)/'Числ характер распред'!$G$18 -> 3.4448215 | N12: 3
A13: Итого: | D13: =SUM(D4:E12) -> 160 | F13: - | H13: - | J13: - | L13: =SUM(L4:M12) -> 152.86763 | N13: =SUM(N4:N12) -> 153
A15: Возраст опрашиваемых, лет | D15: Кол-во программистов (эмперические частоты) | F15: Теоретические частоты | H15: Накопленные эмперические частоты | J15: Накопленные теоретические частоты
D18: f_i | F18: f_m | H18: F_i | J18: F_m
A19: 15 | B19: - | C19: 20 | D19: 6 | F19: 8 | H19: =SUM($D$19:D19) -> 6 | J19: =SUM($F$19:F19) -> 8 | L19: =ABS(H19-J19) -> 2
A20: 20 | B20: - | C20: 25 | D20: 15 | F20: 15 | H20: =SUM($D$19:D20) -> 21 | J20: =SUM($F$19:F20) -> 23 | L20: =ABS(H20-J20) -> 2
A21: 25 | B21: - | C21: 30 | D21: 57 | F21: 23 | H21: =SUM($D$19:D21) -> 78 | J21: =SUM($F$19:F21) -> 46 | L21: =ABS(H21-J21) -> 32
A22: 30 | B22: - | C22: 35 | D22: 17 | F22: 29 | H22: =SUM($D$19:D22) -> 95 | J22: =SUM($F$19:F22) -> 75 | L22: =ABS(H22-J22) -> 20
A23: 35 | B23: - | C23: 40 | D23: 12 | F23: 29 | H23: =SUM($D$19:D23) -> 107 | J23: =SUM($F$19:F23) -> 104 | L23: =ABS(H23-J23) -> 3
A24: 40 | B24: - | C24: 45 | D24: 14 | F24: 23 | H24: =SUM($D$19:D24) -> 121 | J24: =SUM($F$19:F24) -> 127 | L24: =ABS(H24-J24) -> 6
A25: 45 | B25: - | C25: 50 | D25: 20 | F25: 15 | H25: =SUM($D$19:D25) -> 141 | J25: =SUM($F$19:F25) -> 142 | L25: =ABS(H25-J25) -> 1
A26: 50 | B26: - | C26: 55 | D26: 11 | F26: 8 | H26: =SUM($D$19:D26) -> 152 | J26: =SUM($F$19:F26) -> 150 | L26: =ABS(H26-J26) -> 2
A27: 55 | B27: - | C27: 60 | D27: 8 | F27: 3 | H27: =SUM($D$19:D27) -> 160 | J27: =SUM($F$19:F27) -> 153 | L27: =ABS(H27-J27) -> 7
A28: Итого: | D28: =SUM(D19:E27) -> 160 | F28: =SUM(F19:G27) -> 153 | H28: - | J28: - | L28: -
A30: D_max | C30: =MAX(L19:M27) -> 32
B32: λ | C32: =C30/SQRT(D28) -> 2.5298221 | D32: => | F32: P(λ)= | G32: 0 | H32: => | J32: распределение исследуемых данных не соответствует нормальному закону
